Workbook

Sheet Problemas
A1: ID | B1: Mundo | C1: Nivel | D1: Edad sugerida | E1: Tipo de modelo | F1: Enunciado | G1: Dato 1 | H1: Dato 2 | I1: Dato 3 | J1: Respuesta | K1: Operación | L1: Modelo de barras esperado | M1: Pista 1 | N1: Pista 2 | O1: Error típico
A2: M1-N1-01 | B2: Suma y resta | C2: 1 | D2: 6 | E2: Parte-todo | F2: Leo tiene 10 globos y recibe 2 más. ¿Cuántos tiene ahora? | G2: 10 | H2: 2 | J2: =G2+H2 -> 12 | K2: 10 + 2 | L2: Una barra con dos partes (10 y 2) y una llave con '?' sobre el total. | M2: ¿Qué sabes: las partes o el total? | N2: Dibuja una parte de 10 y otra de 2; busca el total. | O2: Restar 10 - 2 en lugar de sumar.
A3: M1-N1-02 | B3: Suma y resta | C3: 1 | D3: 6 | E3: Parte-todo | F3: Pedro tiene 10 caramelos y recibe 5 más. ¿Cuántos tiene ahora? | G3: 10 | H3: 5 | J3: =G3+H3 -> 15 | K3: 10 + 5 | L3: Una barra con dos partes (10 y 5) y una llave con '?' sobre el total. | M3: ¿Qué sabes: las partes o el total? | N3: Dibuja una parte de 10 y otra de 5; busca el total. | O3: Restar 10 - 5 en lugar de sumar.
A4: M1-N1-03 | B4: Suma y resta | C4: 1 | D4: 6 | E4: Parte-todo | F4: Hugo tiene 12 caramelos y recibe 5 más. ¿Cuántos tiene ahora? | G4: 12 | H4: 5 | J4: =G4+H4 -> 17 | K4: 12 + 5 | L4: Una barra con dos partes (12 y 5) y una llave con '?' sobre el total. | M4: ¿Qué sabes: las partes o el total? | N4: Dibuja una parte de 12 y otra de 5; busca el total. | O4: Restar 12 - 5 en lugar de sumar.
A5: M1-N1-04 | B5: Suma y resta | C5: 1 | D5: 6 | E5: Parte-todo | F5: Hugo tiene 7 libros y regala 2. ¿Cuántos le quedan? | G5: 7 | H5: 2 | J5: =G5-H5 -> 5 | K5: 7 - 2 | L5: Barra total de 7, con una parte de 2 y otra parte '?'. | M5: ¿Qué es lo que se conoce: el total o una parte? | N5: La barra entera es 7. Quita la parte de 2. | O5: Sumar los dos números.
A6: M1-N1-05 | B6: Suma y resta | C6: 1 | D6: 6 | E6: Parte-todo | F6: Hugo tiene 6 cromos y regala 4. ¿Cuántos le quedan? | G6: 6 | H6: 4 | J6: =G6-H6 -> 2 | K6: 6 - 4 | L6: Barra total de 6, con una parte de 4 y otra parte '?'. | M6: ¿Qué es lo que se conoce: el total o una parte? | N6: La barra entera es 6. Quita la parte de 4. | O6: Sumar los dos números.
A7: M1-N1-06 | B7: Suma y resta | C7: 1 | D7: 6 | E7: Parte-todo | F7: Leo tiene 6 libros y regala 5. ¿Cuántos le quedan? | G7: 6 | H7: 5 | J7: =G7-H7 -> 1 | K7: 6 - 5 | L7: Barra total de 6, con una parte de 5 y otra parte '?'. | M7: ¿Qué es lo que se conoce: el total o una parte? | N7: La barra entera es 6. Quita la parte de 5. | O7: Sumar los dos números.
A8: M1-N1-07 | B8: Suma y resta | C8: 1 | D8: 6 | E8: Parte-todo | F8: En una caja hay 7 globos; 5 son rojos y el resto azules. ¿Cuántos son azules? | G8: 7 | H8: 5 | J8: =G8-H8 -> 2 | K8: 7 - 5 | L8: Barra total de 7; parte roja de 5; parte azul '?'. | M8: ¿Cuál es el total y cuál es una de las partes? | N8: El resto es la parte que falta de la barra. | O8: Responder con el número de rojos.
A9: M1-N1-08 | B9: Suma y resta | C9: 1 | D9: 6 | E9: Parte-todo | F9: En una caja hay 8 globos; 5 son rojos y el resto azules. ¿Cuántos son azules? | G9: 8 | H9: 5 | J9: =G9-H9 -> 3 | K9: 8 - 5 | L9: Barra total de 8; parte roja de 5; parte azul '?'. | M9: ¿Cuál es el total y cuál es una de las partes? | N9: El resto es la parte que falta de la barra. | O9: Responder con el número de rojos.
A10: M1-N1-09 | B10: Suma y resta | C10: 1 | D10: 6 | E10: Parte-todo | F10: En una caja hay 11 caramelos; 2 son rojos y el resto azules. ¿Cuántos son azules? | G10: 11 | H10: 2 | J10: =G10-H10 -> 9 | K10: 11 - 2 | L10: Barra total de 11; parte roja de 2; parte azul '?'. | M10: ¿Cuál es el total y cuál es una de las partes? | N10: El resto es la parte que falta de la barra. | O10: Responder con el número de rojos.
A11: M1-N1-10 | B11: Suma y resta | C11: 1 | D11: 6 | E11: Parte-todo | F11: Iker tenía algunos globos. Ganó 4 y ahora tiene 6. ¿Cuántos tenía al principio? | G11: 6 | H11: 4 | J11: =G11-H11 -> 2 | K11: 6 - 4 | L11: Barra total de 6; parte ganada de 4; parte inicial '?'. | M11: ¿Qué número es el total final? | N11: Lo que tenía al principio es una parte de la barra final. | O11: Sumar porque 'ganó'.
A12: M1-N1-11 | B12: Suma y resta | C12: 1 | D12: 6 | E12: Parte-todo | F12: Sofía tenía algunos libros. Ganó 4 y ahora tiene 7. ¿Cuántos tenía al principio? | G12: 7 | H12: 4 | J12: =G12-H12 -> 3 | K12: 7 - 4 | L12: Barra total de 7; parte ganada de 4; parte inicial '?'. | M12: ¿Qué número es el total final? | N12: Lo que tenía al principio es una parte de la barra final. | O12: Sumar porque 'ganó'.
A13: M1-N1-12 | B13: Suma y resta | C13: 1 | D13: 6 | E13: Parte-todo | F13: Ana tenía algunos juguetes. Ganó 4 y ahora tiene 8. ¿Cuántos tenía al principio? | G13: 8 | H13: 4 | J13: =G13-H13 -> 4 | K13: 8 - 4 | L13: Barra total de 8; parte ganada de 4; parte inicial '?'. | M13: ¿Qué número es el total final? | N13: Lo que tenía al principio es una parte de la barra final. | O13: Sumar porque 'ganó'.
A14: M1-N2-01 | B14: Suma y resta | C14: 2 | D14: 6-7 | E14: Parte-todo | F14: Dani tiene 30 libros y recibe 20 más. ¿Cuántos tiene ahora? | G14: 30 | H14: 20 | J14: =G14+H14 -> 50 | K14: 30 + 20 | L14: Una barra con dos partes (30 y 20) y una llave con '?' sobre el total. | M14: ¿Qué sabes: las partes o el total? | N14: Dibuja una parte de 30 y otra de 20; busca el total. | O14: Restar 30 - 20 en lugar de sumar.
A15: M1-N2-02 | B15: Suma y resta | C15: 2 | D15: 6-7 | E15: Parte-todo | F15: Hugo tiene 56 caramelos y recibe 11 más. ¿Cuántos tiene ahora? | G15: 56 | H15: 11 | J15: =G15+H15 -> 67 | K15: 56 + 11 | L15: Una barra con dos partes (56 y 11) y una llave con '?' sobre el total. | M15: ¿Qué sabes: las partes o el total? | N15: Dibuja una parte de 56 y otra de 11; busca el total. | O15: Restar 56 - 11 en lugar de sumar.
A16: M1-N2-03 | B16: Suma y resta | C16: 2 | D16: 6-7 | E16: Parte-todo | F16: Julia tiene 56 caramelos y recibe 20 más. ¿Cuántos tiene ahora? | G16: 56 | H16: 20 | J16: =G16+H16 -> 76 | K16: 56 + 20 | L16: Una barra con dos partes (56 y 20) y una llave con '?' sobre el total. | M16: ¿Qué sabes: las partes o el total? | N16: Dibuja una parte de 56 y otra de 20; busca el total. | O16: Restar 56 - 20 en lugar de sumar.
A17: M1-N2-04 | B17: Suma y resta | C17: 2 | D17: 6-7 | E17: Parte-todo | F17: Lola tiene 51 globos y regala 23. ¿Cuántos le quedan? | G17: 51 | H17: 23 | J17: =G17-H17 -> 28 | K17: 51 - 23 | L17: Barra total de 51, con una parte de 23 y otra parte '?'. | M17: ¿Qué es lo que se conoce: el total o una parte? | N17: La barra entera es 51. Quita la parte de 23. | O17: Sumar los dos números.
A18: M1-N2-05 | B18: Suma y resta | C18: 2 | D18: 6-7 | E18: Parte-todo | F18: Lola tiene 26 caramelos y regala 15. ¿Cuántos le quedan? | G18: 26 | H18: 15 | J18: =G18-H18 -> 11 | K18: 26 - 15 | L18: Barra total de 26, con una parte de 15 y otra parte '?'. | M18: ¿Qué es lo que se conoce: el total o una parte? | N18: La barra entera es 26. Quita la parte de 15. | O18: Sumar los dos números.
A19: M1-N2-06 | B19: Suma y resta | C19: 2 | D19: 6-7 | E19: Parte-todo | F19: Marta tiene 58 cromos y regala 11. ¿Cuántos le quedan? | G19: 58 | H19: 11 | J19: =G19-H19 -> 47 | K19: 58 - 11 | L19: Barra total de 58, con una parte de 11 y otra parte '?'. | M19: ¿Qué es lo que se conoce: el total o una parte? | N19: La barra entera es 58. Quita la parte de 11. | O19: Sumar los dos números.
A20: M1-N2-07 | B20: Suma y resta | C20: 2 | D20: 6-7 | E20: Parte-todo | F20: En una caja hay 52 caramelos; 23 son rojos y el resto azules. ¿Cuántos son azules? | G20: 52 | H20: 23 | J20: =G20-H20 -> 29 | K20: 52 - 23 | L20: Barra total de 52; parte roja de 23; parte azul '?'. | M20: ¿Cuál es el total y cuál es una de las partes? | N20: El resto es la parte que falta de la barra. | O20: Responder con el número de rojos.
A21: M1-N2-08 | B21: Suma y resta | C21: 2 | D21: 6-7 | E21: Parte-todo | F21: En una caja hay 39 libros; 11 son rojos y el resto azules. ¿Cuántos son azules? | G21: 39 | H21: 11 | J21: =G21-H21 -> 28 | K21: 39 - 11 | L21: Barra total de 39; parte roja de 11; parte azul '?'. | M21: ¿Cuál es el total y cuál es una de las partes? | N21: El resto es la parte que falta de la barra. | O21: Responder con el número de rojos.
A22: M1-N2-09 | B22: Suma y resta | C22: 2 | D22: 6-7 | E22: Parte-todo | F22: En una caja hay 54 juguetes; 23 son rojos y el resto azules. ¿Cuántos son azules? | G22: 54 | H22: 23 | J22: =G22-H22 -> 31 | K22: 54 - 23 | L22: Barra total de 54; parte roja de 23; parte azul '?'. | M22: ¿Cuál es el total y cuál es una de las partes? | N22: El resto es la parte que falta de la barra. | O22: Responder con el número de rojos.
A23: M1-N2-10 | B23: Suma y resta | C23: 2 | D23: 6-7 | E23: Parte-todo | F23: Iker tenía algunos caramelos. Ganó 20 y ahora tiene 41. ¿Cuántos tenía al principio? | G23: 41 | H23: 20 | J23: =G23-H23 -> 21 | K23: 41 - 20 | L23: Barra total de 41; parte ganada de 20; parte inicial '?'. | M23: ¿Qué número es el total final? | N23: Lo que tenía al principio es una parte de la barra final. | O23: Sumar porque 'ganó'.
A24: M1-N2-11 | B24: Suma y resta | C24: 2 | D24: 6-7 | E24: Parte-todo | F24: Carla tenía algunos globos. Ganó 24 y ahora tiene 60. ¿Cuántos tenía al principio? | G24: 60 | H24: 24 | J24: =G24-H24 -> 36 | K24: 60 - 24 | L24: Barra total de 60; parte ganada de 24; parte inicial '?'. | M24: ¿Qué número es el total final? | N24: Lo que tenía al principio es una parte de la barra final. | O24: Sumar porque 'ganó'.
A25: M1-N2-12 | B25: Suma y resta | C25: 2 | D25: 6-7 | E25: Parte-todo | F25: Iker tenía algunos libros. Ganó 21 y ahora tiene 50. ¿Cuántos tenía al principio? | G25: 50 | H25: 21 | J25: =G25-H25 -> 29 | K25: 50 - 21 | L25: Barra total de 50; parte ganada de 21; parte inicial '?'. | M25: ¿Qué número es el total final? | N25: Lo que tenía al principio es una parte de la barra final. | O25: Sumar porque 'ganó'.
A26: M1-N3-01 | B26: Suma y resta | C26: 3 | D26: 7 | E26: Parte-todo | F26: Pedro tiene 77 globos y recibe 15 más. ¿Cuántos tiene ahora? | G26: 77 | H26: 15 | J26: =G26+H26 -> 92 | K26: 77 + 15 | L26: Una barra con dos partes (77 y 15) y una llave con '?' sobre el total. | M26: ¿Qué sabes: las partes o el total? | N26: Dibuja una parte de 77 y otra de 15; busca el total. | O26: Restar 77 - 15 en lugar de sumar.
A27: M1-N3-02 | B27: Suma y resta | C27: 3 | D27: 7 | E27: Parte-todo | F27: Ana tiene 98 lápices y recibe 45 más. ¿Cuántos tiene ahora? | G27: 98 | H27: 45 | J27: =G27+H27 -> 143 | K27: 98 + 45 | L27: Una barra con dos partes (98 y 45) y una llave con '?' sobre el total. | M27: ¿Qué sabes: las partes o el total? | N27: Dibuja una parte de 98 y otra de 45; busca el total. | O27: Restar 98 - 45 en lugar de sumar.
A28: M1-N3-03 | B28: Suma y resta | C28: 3 | D28: 7 | E28: Parte-todo | F28: Dani tiene 91 caramelos y recibe 26 más. ¿Cuántos tiene ahora? | G28: 91 | H28: 26 | J28: =G28+H28 -> 117 | K28: 91 + 26 | L28: Una barra con dos partes (91 y 26) y una llave con '?' sobre el total. | M28: ¿Qué sabes: las partes o el total? | N28: Dibuja una parte de 91 y otra de 26; busca el total. | O28: Restar 91 - 26 en lugar de sumar.
A29: M1-N3-04 | B29: Suma y resta | C29: 3 | D29: 7 | E29: Parte-todo | F29: Pedro tiene 91 globos y regala 29. ¿Cuántos le quedan? | G29: 91 | H29: 29 | J29: =G29-H29 -> 62 | K29: 91 - 29 | L29: Barra total de 91, con una parte de 29 y otra parte '?'. | M29: ¿Qué es lo que se conoce: el total o una parte? | N29: La barra entera es 91. Quita la parte de 29. | O29: Sumar los dos números.
A30: M1-N3-05 | B30: Suma y resta | C30: 3 | D30: 7 | E30: Parte-todo | F30: Lola tiene 87 libros y regala 32. ¿Cuántos le quedan? | G30: 87 | H30: 32 | J30: =G30-H30 -> 55 | K30: 87 - 32 | L30: Barra total de 87, con una parte de 32 y otra parte '?'. | M30: ¿Qué es lo que se conoce: el total o una parte? | N30: La barra entera es 87. Quita la parte de 32. | O30: Sumar los dos números.
A31: M1-N3-06 | B31: Suma y resta | C31: 3 | D31: 7 | E31: Parte-todo | F31: Carla tiene 78 cromos y regala 25. ¿Cuántos le quedan? | G31: 78 | H31: 25 | J31: =G31-H31 -> 53 | K31: 78 - 25 | L31: Barra total de 78, con una parte de 25 y otra parte '?'. | M31: ¿Qué es lo que se conoce: el total o una parte? | N31: La barra entera es 78. Quita la parte de 25. | O31: Sumar los dos números.
A32: M1-N3-07 | B32: Suma y resta | C32: 3 | D32: 7 | E32: Parte-todo | F32: En una caja hay 88 cromos; 37 son rojos y el resto azules. ¿Cuántos son azules? | G32: 88 | H32: 37 | J32: =G32-H32 -> 51 | K32: 88 - 37 | L32: Barra total de 88; parte roja de 37; parte azul '?'. | M32: ¿Cuál es el total y cuál es una de las partes? | N32: El resto es la parte que falta de la barra. | O32: Responder con el número de rojos.
A33: M1-N3-08 | B33: Suma y resta | C33: 3 | D33: 7 | E33: Parte-todo | F33: En una caja hay 76 caramelos; 29 son rojos y el resto azules. ¿Cuántos son azules? | G33: 76 | H33: 29 | J33: =G33-H33 -> 47 | K33: 76 - 29 | L33: Barra total de 76; parte roja de 29; parte azul '?'. | M33: ¿Cuál es el total y cuál es una de las partes? | N33: El resto es la parte que falta de la barra. | O33: Responder con el número de rojos.
A34: M1-N3-09 | B34: Suma y resta | C34: 3 | D34: 7 | E34: Parte-todo | F34: En una caja hay 90 libros; 45 son rojos y el resto azules. ¿Cuántos son azules? | G34: 90 | H34: 45 | J34: =G34-H34 -> 45 | K34: 90 - 45 | L34: Barra total de 90; parte roja de 45; parte azul '?'. | M34: ¿Cuál es el total y cuál es una de las partes? | N34: El resto es la parte que falta de la barra. | O34: Responder con el número de rojos.
A35: M1-N3-10 | B35: Suma y resta | C35: 3 | D35: 7 | E35: Parte-todo | F35: Leo tenía algunos juguetes. Ganó 43 y ahora tiene 77. ¿Cuántos tenía al principio? | G35: 77 | H35: 43 | J35: =G35-H35 -> 34 | K35: 77 - 43 | L35: Barra total de 77; parte ganada de 43; parte inicial '?'. | M35: ¿Qué número es el total final? | N35: Lo que tenía al principio es una parte de la barra final. | O35: Sumar porque 'ganó'.
A36: M1-N3-11 | B36: Suma y resta | C36: 3 | D36: 7 | E36: Parte-todo | F36: Dani tenía algunos globos. Ganó 21 y ahora tiene 66. ¿Cuántos tenía al principio? | G36: 66 | H36: 21 | J36: =G36-H36 -> 45 | K36: 66 - 21 | L36: Barra total de 66; parte ganada de 21; parte inicial '?'. | M36: ¿Qué número es el total final? | N36: Lo que tenía al principio es una parte de la barra final. | O36: Sumar porque 'ganó'.
A37: M1-N3-12 | B37: Suma y resta | C37: 3 | D37: 7 | E37: Parte-todo | F37: Iker tenía algunos libros. Ganó 29 y ahora tiene 69. ¿Cuántos tenía al principio? | G37: 69 | H37: 29 | J37: =G37-H37 -> 40 | K37: 69 - 29 | L37: Barra total de 69; parte ganada de 29; parte inicial '?'. | M37: ¿Qué número es el total final? | N37: Lo que tenía al principio es una parte de la barra final. | O37: Sumar porque 'ganó'.
A38: M2-N1-01 | B38: Comparación | C38: 1 | D38: 7-8 | E38: Comparación | F38: Ana tiene 17 cromos y Leo tiene 6 más que Ana. ¿Cuántos tiene Leo? | G38: 17 | H38: 6 | J38: =G38+H38 -> 23 | K38: 17 + 6 | L38: Barra de Ana = 17; barra de Leo = 17 + bloque de 6; '?' en la barra de Leo. | M38: ¿Quién tiene más, Ana o Leo? | N38: La barra de Leo empieza igual y añade 6. | O38: Responder 6 (solo la diferencia).
A39: M2-N1-02 | B39: Comparación | C39: 1 | D39: 7-8 | E39: Comparación | F39: Lola tiene 13 caramelos y Leo tiene 3 más que Lola. ¿Cuántos tiene Leo? | G39: 13 | H39: 3 | J39: =G39+H39 -> 16 | K39: 13 + 3 | L39: Barra de Lola = 13; barra de Leo = 13 + bloque de 3; '?' en la barra de Leo. | M39: ¿Quién tiene más, Lola o Leo? | N39: La barra de Leo empieza igual y añade 3. | O39: Responder 3 (solo la diferencia).
A40: M2-N1-03 | B40: Comparación | C40: 1 | D40: 7-8 | E40: Comparación | F40: Leo tiene 18 cromos y Hugo tiene 4 más que Leo. ¿Cuántos tiene Hugo? | G40: 18 | H40: 4 | J40: =G40+H40 -> 22 | K40: 18 + 4 | L40: Barra de Leo = 18; barra de Hugo = 18 + bloque de 4; '?' en la barra de Hugo. | M40: ¿Quién tiene más, Leo o Hugo? | N40: La barra de Hugo empieza igual y añade 4. | O40: Responder 4 (solo la diferencia).
...

Sheet Resumen
A1: Mundo | B1: Nivel 1 | C1: Nivel 2 | D1: Nivel 3 | E1: Total
A2: Suma y resta | B2: =COUNTIFS(Problemas!$B:$B,$A2,Problemas!$C:$C,1) -> 12 | C2: =COUNTIFS(Problemas!$B:$B,$A2,Problemas!$C:$C,2) -> 12 | D2: =COUNTIFS(Problemas!$B:$B,$A2,Problemas!$C:$C,3) -> 12 | E2: =SUM(B2:D2) -> 36
A3: Comparación | B3: =COUNTIFS(Problemas!$B:$B,$A3,Problemas!$C:$C,1) -> 12 | C3: =COUNTIFS(Problemas!$B:$B,$A3,Problemas!$C:$C,2) -> 12 | D3: =COUNTIFS(Problemas!$B:$B,$A3,Problemas!$C:$C,3) -> 12 | E3: =SUM(B3:D3) -> 36
A4: Fracciones | B4: =COUNTIFS(Problemas!$B:$B,$A4,Problemas!$C:$C,1) -> 12 | C4: =COUNTIFS(Problemas!$B:$B,$A4,Problemas!$C:$C,2) -> 12 | D4: =COUNTIFS(Problemas!$B:$B,$A4,Problemas!$C:$C,3) -> 12 | E4: =SUM(B4:D4) -> 36
A5: Multiplicar y dividir | B5: =COUNTIFS(Problemas!$B:$B,$A5,Problemas!$C:$C,1) -> 12 | C5: =COUNTIFS(Problemas!$B:$B,$A5,Problemas!$C:$C,2) -> 12 | D5: =COUNTIFS(Problemas!$B:$B,$A5,Problemas!$C:$C,3) -> 12 | E5: =SUM(B5:D5) -> 36
A6: Total | B6: =SUM(B2:B5) -> 48 | C6: =SUM(C2:C5) -> 48 | D6: =SUM(D2:D5) -> 48 | E6: =SUM(E2:E5) -> 144

Sheet Instrucciones
A1: Banco de problemas de Barri (método Singapur, modelo de barras)
A2: Texto azul en Dato 1-3: valores de entrada. La columna Respuesta se calcula con fórmula a partir de ellos.
A3: Si cambias un dato, actualiza a mano también el enunciado, la operación y el modelo de barras (son texto).
A4: Dato 3 solo se usa en fracciones (numerador). En fracciones: Dato 1 = total (o parte conocida), Dato 2 = denominador.
A5: Los problemas se generaron a partir de plantillas con nombres y números variados; conviene revisarlos con el grupo antes de usarlos.
A6: Edad sugerida y niveles son orientativos.
